Traning started.....
../AdversarialExecutor/data_queue/
../AdversarialExecutor/data_queue/
../AdversarialExecutor/data_queue/
Wating for data....
Wating for data....
Wating for data....
../AdversarialExecutor/data_queue/
Wating for data....
Wating for data....
Wating for data....
Wating for data....
Wating for data....
Wating for data....
Wating for data....
Wating for data....
Wating for data....
Wating for data....
Wating for data....
Wating for data....
Wating for data....
Wating for data....
Wating for data....
Wating for data....
Wating for data....
Wating for data....
Wating for data....
Wating for data....
Wating for data....
Wating for data....
Wating for data....
Wating for data....
Wating for data....
Wating for data....
Wating for data....
Wating for data....
Wating for data....
Wating for data....
Wating for data....
Wating for data....
Wating for data....
Wating for data....
Wating for data....
Wating for data....
Wating for data....
Wating for data....
Wating for data....
Wating for data....
Wating for data....
Wating for data....
Wating for data....
Wating for data....
Wating for data....
Wating for data....
Wating for data....
Wating for data....
Wating for data....
Wating for data....
Wating for data....
Wating for data....
Wating for data....
Wating for data....
Wating for data....
Wating for data....
Wating for data....
Wating for data....
Wating for data....
Wating for data....
Wating for data....
Wating for data....
Wating for data....
Wating for data....
Wating for data....
Wating for data....
Wating for data....
Wating for data....
Wating for data....
Wating for data....
Wating for data....
Wating for data....
Wating for data....
Traceback (most recent call last):
  File "start_traning.py", line 41, in <module>
    train(CONFIG_PATH, CONFIG, "cuda:0", train_loader_adversarial, val_loader_adversarial, val_loader)
  File "/srv/data/halmosi/ADVERSARIAL_TRANING_SEGMENTATION/AdversarialTraning/Trainer/Train.py", line 39, in train
    for data in train_loader_adversarial:
  File "/srv/data/halmosi/anaconda3/envs/pytorch/lib/python3.6/site-packages/torch/utils/data/dataloader.py", line 521, in __next__
    data = self._next_data()
  File "/srv/data/halmosi/anaconda3/envs/pytorch/lib/python3.6/site-packages/torch/utils/data/dataloader.py", line 1203, in _next_data
    return self._process_data(data)
  File "/srv/data/halmosi/anaconda3/envs/pytorch/lib/python3.6/site-packages/torch/utils/data/dataloader.py", line 1229, in _process_data
    data.reraise()
  File "/srv/data/halmosi/anaconda3/envs/pytorch/lib/python3.6/site-packages/torch/_utils.py", line 434, in reraise
    raise exception
RuntimeError: Caught RuntimeError in DataLoader worker process 0.
Original Traceback (most recent call last):
  File "/srv/data/halmosi/anaconda3/envs/pytorch/lib/python3.6/site-packages/torch/utils/data/_utils/worker.py", line 287, in _worker_loop
    data = fetcher.fetch(index)
  File "/srv/data/halmosi/anaconda3/envs/pytorch/lib/python3.6/site-packages/torch/utils/data/_utils/fetch.py", line 49, in fetch
    data = [self.dataset[idx] for idx in possibly_batched_index]
  File "/srv/data/halmosi/anaconda3/envs/pytorch/lib/python3.6/site-packages/torch/utils/data/_utils/fetch.py", line 49, in <listcomp>
    data = [self.dataset[idx] for idx in possibly_batched_index]
  File "../AdversarialLoader/Dataset.py", line 41, in __getitem__
    images.append(torch.load(image_path))
  File "/srv/data/halmosi/anaconda3/envs/pytorch/lib/python3.6/site-packages/torch/serialization.py", line 607, in load
    return _load(opened_zipfile, map_location, pickle_module, **pickle_load_args)
  File "/srv/data/halmosi/anaconda3/envs/pytorch/lib/python3.6/site-packages/torch/serialization.py", line 882, in _load
    result = unpickler.load()
  File "/srv/data/halmosi/anaconda3/envs/pytorch/lib/python3.6/site-packages/torch/serialization.py", line 857, in persistent_load
    load_tensor(data_type, size, key, _maybe_decode_ascii(location))
  File "/srv/data/halmosi/anaconda3/envs/pytorch/lib/python3.6/site-packages/torch/serialization.py", line 846, in load_tensor
    loaded_storages[key] = restore_location(storage, location)
  File "/srv/data/halmosi/anaconda3/envs/pytorch/lib/python3.6/site-packages/torch/serialization.py", line 175, in default_restore_location
    result = fn(storage, location)
  File "/srv/data/halmosi/anaconda3/envs/pytorch/lib/python3.6/site-packages/torch/serialization.py", line 157, in _cuda_deserialize
    return obj.cuda(device)
  File "/srv/data/halmosi/anaconda3/envs/pytorch/lib/python3.6/site-packages/torch/_utils.py", line 71, in _cuda
    with torch.cuda.device(device):
  File "/srv/data/halmosi/anaconda3/envs/pytorch/lib/python3.6/site-packages/torch/cuda/__init__.py", line 272, in __enter__
    self.prev_idx = torch.cuda.current_device()
  File "/srv/data/halmosi/anaconda3/envs/pytorch/lib/python3.6/site-packages/torch/cuda/__init__.py", line 479, in current_device
    _lazy_init()
  File "/srv/data/halmosi/anaconda3/envs/pytorch/lib/python3.6/site-packages/torch/cuda/__init__.py", line 205, in _lazy_init
    "Cannot re-initialize CUDA in forked subprocess. To use CUDA with "
RuntimeError: Cannot re-initialize CUDA in forked subprocess. To use CUDA with multiprocessing, you must use the 'spawn' start method
Wating for data....
Wating for data....
Wating for data....
Wating for data....
Wating for data....
Wating for data....
Wating for data....
Wating for data....
Wating for data....
Wating for data....
Wating for data....
Wating for data....
../AdversarialExecutor/data_queue/
../AdversarialExecutor/data_queue/
../AdversarialExecutor/data_queue/
../AdversarialExecutor/data_queue/
../AdversarialExecutor/data_queue/